2024-10-20 20:28:18,315 - app - ERROR - Exception on / [GET]
Traceback (most recent call last):
  File "/home/franco/Escritorio/uvlhub_practicas/entv/lib/python3.12/site-packages/sqlalchemy/engine/base.py", line 1967, in _exec_single_context
    self.dialect.do_execute(
  File "/home/franco/Escritorio/uvlhub_practicas/entv/lib/python3.12/site-packages/sqlalchemy/engine/default.py", line 924, in do_execute
    cursor.execute(statement, parameters)
  File "/home/franco/Escritorio/uvlhub_practicas/entv/lib/python3.12/site-packages/pymysql/cursors.py", line 153, in execute
    result = self._query(query)
             ^^^^^^^^^^^^^^^^^^
  File "/home/franco/Escritorio/uvlhub_practicas/entv/lib/python3.12/site-packages/pymysql/cursors.py", line 322, in _query
    conn.query(q)
  File "/home/franco/Escritorio/uvlhub_practicas/entv/lib/python3.12/site-packages/pymysql/connections.py", line 563, in query
    self._affected_rows = self._read_query_result(unbuffered=unbuffered)
                          ^^^^^^^^^^^^^^^^^^^^^^^^^^^^^^^^^^^^^^^^^^^^^^
  File "/home/franco/Escritorio/uvlhub_practicas/entv/lib/python3.12/site-packages/pymysql/connections.py", line 825, in _read_query_result
    result.read()
  File "/home/franco/Escritorio/uvlhub_practicas/entv/lib/python3.12/site-packages/pymysql/connections.py", line 1199, in read
    first_packet = self.connection._read_packet()
                   ^^^^^^^^^^^^^^^^^^^^^^^^^^^^^^
  File "/home/franco/Escritorio/uvlhub_practicas/entv/lib/python3.12/site-packages/pymysql/connections.py", line 775, in _read_packet
    packet.raise_for_error()
  File "/home/franco/Escritorio/uvlhub_practicas/entv/lib/python3.12/site-packages/pymysql/protocol.py", line 219, in raise_for_error
    err.raise_mysql_exception(self._data)
  File "/home/franco/Escritorio/uvlhub_practicas/entv/lib/python3.12/site-packages/pymysql/err.py", line 150, in raise_mysql_exception
    raise errorclass(errno, errval)
pymysql.err.ProgrammingError: (1146, "Table 'uvlhubdb.ds_view_record' doesn't exist")

The above exception was the direct cause of the following exception:

Traceback (most recent call last):
  File "/home/franco/Escritorio/uvlhub_practicas/entv/lib/python3.12/site-packages/flask/app.py", line 1473, in wsgi_app
    response = self.full_dispatch_request()
               ^^^^^^^^^^^^^^^^^^^^^^^^^^^^
  File "/home/franco/Escritorio/uvlhub_practicas/entv/lib/python3.12/site-packages/flask/app.py", line 882, in full_dispatch_request
    rv = self.handle_user_exception(e)
         ^^^^^^^^^^^^^^^^^^^^^^^^^^^^^
  File "/home/franco/Escritorio/uvlhub_practicas/entv/lib/python3.12/site-packages/flask_restful/__init__.py", line 298, in error_router
    return original_handler(e)
           ^^^^^^^^^^^^^^^^^^^
  File "/home/franco/Escritorio/uvlhub_practicas/entv/lib/python3.12/site-packages/flask/app.py", line 880, in full_dispatch_request
    rv = self.dispatch_request()
         ^^^^^^^^^^^^^^^^^^^^^^^
  File "/home/franco/Escritorio/uvlhub_practicas/entv/lib/python3.12/site-packages/flask/app.py", line 865, in dispatch_request
    return self.ensure_sync(self.view_functions[rule.endpoint])(**view_args)  # type: ignore[no-any-return]
           ^^^^^^^^^^^^^^^^^^^^^^^^^^^^^^^^^^^^^^^^^^^^^^^^^^^^^^^^^^^^^^^^^
  File "/home/franco/Escritorio/uvlhub_practicas/app/modules/public/routes.py", line 27, in index
    total_dataset_views = dataset_service.total_dataset_views()
                          ^^^^^^^^^^^^^^^^^^^^^^^^^^^^^^^^^^^^^
  File "/home/franco/Escritorio/uvlhub_practicas/app/modules/dataset/services.py", line 93, in total_dataset_views
    return self.dsviewrecord_repostory.total_dataset_views()
           ^^^^^^^^^^^^^^^^^^^^^^^^^^^^^^^^^^^^^^^^^^^^^^^^^
  File "/home/franco/Escritorio/uvlhub_practicas/app/modules/dataset/repositories.py", line 48, in total_dataset_views
    max_id = self.model.query.with_entities(func.max(self.model.id)).scalar()
             ^^^^^^^^^^^^^^^^^^^^^^^^^^^^^^^^^^^^^^^^^^^^^^^^^^^^^^^^^^^^^^^^
  File "/home/franco/Escritorio/uvlhub_practicas/entv/lib/python3.12/site-packages/sqlalchemy/orm/query.py", line 2805, in scalar
    ret = self.one()
          ^^^^^^^^^^
  File "/home/franco/Escritorio/uvlhub_practicas/entv/lib/python3.12/site-packages/sqlalchemy/orm/query.py", line 2778, in one
    return self._iter().one()  # type: ignore
           ^^^^^^^^^^^^
  File "/home/franco/Escritorio/uvlhub_practicas/entv/lib/python3.12/site-packages/sqlalchemy/orm/query.py", line 2827, in _iter
    result: Union[ScalarResult[_T], Result[_T]] = self.session.execute(
                                                  ^^^^^^^^^^^^^^^^^^^^^
  File "/home/franco/Escritorio/uvlhub_practicas/entv/lib/python3.12/site-packages/sqlalchemy/orm/session.py", line 2351, in execute
    return self._execute_internal(
           ^^^^^^^^^^^^^^^^^^^^^^^
  File "/home/franco/Escritorio/uvlhub_practicas/entv/lib/python3.12/site-packages/sqlalchemy/orm/session.py", line 2236, in _execute_internal
    result: Result[Any] = compile_state_cls.orm_execute_statement(
                          ^^^^^^^^^^^^^^^^^^^^^^^^^^^^^^^^^^^^^^^^
  File "/home/franco/Escritorio/uvlhub_practicas/entv/lib/python3.12/site-packages/sqlalchemy/orm/context.py", line 293, in orm_execute_statement
    result = conn.execute(
             ^^^^^^^^^^^^^
  File "/home/franco/Escritorio/uvlhub_practicas/entv/lib/python3.12/site-packages/sqlalchemy/engine/base.py", line 1418, in execute
    return meth(
           ^^^^^
  File "/home/franco/Escritorio/uvlhub_practicas/entv/lib/python3.12/site-packages/sqlalchemy/sql/elements.py", line 515, in _execute_on_connection
    return connection._execute_clauseelement(
           ^^^^^^^^^^^^^^^^^^^^^^^^^^^^^^^^^^
  File "/home/franco/Escritorio/uvlhub_practicas/entv/lib/python3.12/site-packages/sqlalchemy/engine/base.py", line 1640, in _execute_clauseelement
    ret = self._execute_context(
          ^^^^^^^^^^^^^^^^^^^^^^
  File "/home/franco/Escritorio/uvlhub_practicas/entv/lib/python3.12/site-packages/sqlalchemy/engine/base.py", line 1846, in _execute_context
    return self._exec_single_context(
           ^^^^^^^^^^^^^^^^^^^^^^^^^^
  File "/home/franco/Escritorio/uvlhub_practicas/entv/lib/python3.12/site-packages/sqlalchemy/engine/base.py", line 1986, in _exec_single_context
    self._handle_dbapi_exception(
  File "/home/franco/Escritorio/uvlhub_practicas/entv/lib/python3.12/site-packages/sqlalchemy/engine/base.py", line 2353, in _handle_dbapi_exception
    raise sqlalchemy_exception.with_traceback(exc_info[2]) from e
  File "/home/franco/Escritorio/uvlhub_practicas/entv/lib/python3.12/site-packages/sqlalchemy/engine/base.py", line 1967, in _exec_single_context
    self.dialect.do_execute(
  File "/home/franco/Escritorio/uvlhub_practicas/entv/lib/python3.12/site-packages/sqlalchemy/engine/default.py", line 924, in do_execute
    cursor.execute(statement, parameters)
  File "/home/franco/Escritorio/uvlhub_practicas/entv/lib/python3.12/site-packages/pymysql/cursors.py", line 153, in execute
    result = self._query(query)
             ^^^^^^^^^^^^^^^^^^
  File "/home/franco/Escritorio/uvlhub_practicas/entv/lib/python3.12/site-packages/pymysql/cursors.py", line 322, in _query
    conn.query(q)
  File "/home/franco/Escritorio/uvlhub_practicas/entv/lib/python3.12/site-packages/pymysql/connections.py", line 563, in query
    self._affected_rows = self._read_query_result(unbuffered=unbuffered)
                          ^^^^^^^^^^^^^^^^^^^^^^^^^^^^^^^^^^^^^^^^^^^^^^
  File "/home/franco/Escritorio/uvlhub_practicas/entv/lib/python3.12/site-packages/pymysql/connections.py", line 825, in _read_query_result
    result.read()
  File "/home/franco/Escritorio/uvlhub_practicas/entv/lib/python3.12/site-packages/pymysql/connections.py", line 1199, in read
    first_packet = self.connection._read_packet()
                   ^^^^^^^^^^^^^^^^^^^^^^^^^^^^^^
  File "/home/franco/Escritorio/uvlhub_practicas/entv/lib/python3.12/site-packages/pymysql/connections.py", line 775, in _read_packet
    packet.raise_for_error()
  File "/home/franco/Escritorio/uvlhub_practicas/entv/lib/python3.12/site-packages/pymysql/protocol.py", line 219, in raise_for_error
    err.raise_mysql_exception(self._data)
  File "/home/franco/Escritorio/uvlhub_practicas/entv/lib/python3.12/site-packages/pymysql/err.py", line 150, in raise_mysql_exception
    raise errorclass(errno, errval)
sqlalchemy.exc.ProgrammingError: (pymysql.err.ProgrammingError) (1146, "Table 'uvlhubdb.ds_view_record' doesn't exist")
[SQL: SELECT max(ds_view_record.id) AS max_1 
FROM ds_view_record]
(Background on this error at: https://sqlalche.me/e/20/f405)
